Build started 8/20/2018 10:59:29 PM.
Test run for C:\Users\stearm01\source\xBDD\MySample.Features\bin\Debug\netcoreapp2.1\Code\bin\Debug\netcoreapp2.1\MySample.Features.dll(.NETCoreApp,Version=v2.1)
Microsoft (R) Test Execution Command Line Tool Version 15.7.0
Copyright (c) Microsoft Corporation.  All rights reserved.

Starting test execution, please wait...
Failed   MyFirstScenario
Error Message:
 Test method MySample.Features.MyFirstArea.MyFirstFailingFeature.MyFirstScenario threw exception: 
xBDD.StepException: The step 'my step 2' threw a 'Exception' exception with a message: 'Exception of type 'System.Exception' was thrown.'. See the inner exception for details. ---> System.Exception: Exception of type 'System.Exception' was thrown.
Stack Trace:
    at MySample.Features.MyFirstArea.MyFirstFailingFeature.<>c.<MyFirstScenario>b__0_1(Step s) in C:\Users\stearm01\source\xBDD\MySample.Features\bin\Debug\netcoreapp2.1\Code\MyFirstArea\MyFirstFailingFeature.cs:line 21
   at System.Threading.ExecutionContext.RunInternal(ExecutionContext executionContext, ContextCallback callback, Object state)
--- End of stack trace from previous location where exception was thrown ---
   at System.Threading.Tasks.Task.ExecuteWithThreadLocal(Task& currentTaskSlot)
--- End of stack trace from previous location where exception was thrown ---
   at xBDD.Core.StepExecutor.ExecuteStepAsync(Step step)
--- End of inner exception stack trace ---
    at xBDD.Core.StepExceptionHandler.ProcessException(StepExecutor stepExecutor, Step step, Exception ex)
   at xBDD.Core.StepExecutor.ExecuteStepAsync(Step step)
   at xBDD.Core.ScenarioRunner.RunAsync(Boolean passWhenNoAction)
   at xBDD.Core.ScenarioBuilder.Run()
   at MySample.Features.MyFirstArea.MyFirstFailingFeature.MyFirstScenario() in C:\Users\stearm01\source\xBDD\MySample.Features\bin\Debug\netcoreapp2.1\Code\MyFirstArea\MyFirstFailingFeature.cs:line 19

Standard Output Messages:
 

Debug Trace:
My First Scenario
     Given my step 1
     When my step 2
     Then my step 3


Passed   MyFirstScenario
Failed   MyScenario_40_Failed
Error Message:
 Test method MySample.Features.MyArea_7_AllFailed.MyFeature_16_AllFailed.MyScenario_40_Failed threw exception: 
xBDD.StepException: The step 'my step 119 failed' threw a 'Exception' exception with a message: 'Exception of type 'System.Exception' was thrown.'. See the inner exception for details. ---> System.Exception: Exception of type 'System.Exception' was thrown.
Stack Trace:
    at MySample.Features.MyArea_7_AllFailed.MyFeature_16_AllFailed.<>c.<MyScenario_40_Failed>b__0_1(Step s) in C:\Users\stearm01\source\xBDD\MySample.Features\bin\Debug\netcoreapp2.1\Code\MyArea_7_AllFailed\MyFeature_16_AllFailed.cs:line 21
   at System.Threading.ExecutionContext.RunInternal(ExecutionContext executionContext, ContextCallback callback, Object state)
--- End of stack trace from previous location where exception was thrown ---
   at System.Threading.Tasks.Task.ExecuteWithThreadLocal(Task& currentTaskSlot)
--- End of stack trace from previous location where exception was thrown ---
   at xBDD.Core.StepExecutor.ExecuteStepAsync(Step step)
--- End of inner exception stack trace ---
    at xBDD.Core.StepExceptionHandler.ProcessException(StepExecutor stepExecutor, Step step, Exception ex)
   at xBDD.Core.StepExecutor.ExecuteStepAsync(Step step)
   at xBDD.Core.ScenarioRunner.RunAsync(Boolean passWhenNoAction)
   at xBDD.Core.ScenarioBuilder.Run()
   at MySample.Features.MyArea_7_AllFailed.MyFeature_16_AllFailed.MyScenario_40_Failed() in C:\Users\stearm01\source\xBDD\MySample.Features\bin\Debug\netcoreapp2.1\Code\MyArea_7_AllFailed\MyFeature_16_AllFailed.cs:line 19

Standard Output Messages:
 

Debug Trace:
My Scenario 40 Failed
     Given my step 118
     When my step 119 failed
     Then my step 120


Skipped  MyScenario_39_AllSkipped
Passed   MyScenario_32_Unsorted_36_Sorted
Passed   MyScenario_31_Unsorted_37_Sorted
Failed   MyScenario_30_Unsorted_38_Sorted
Error Message:
 Test method MySample.Features.MyArea_5_SortFlip.MyFeature_12_Third.MyScenario_30_Unsorted_38_Sorted threw exception: 
xBDD.StepException: The step 'my step 89 113 failed' threw a 'Exception' exception with a message: 'Exception of type 'System.Exception' was thrown.'. See the inner exception for details. ---> System.Exception: Exception of type 'System.Exception' was thrown.
Stack Trace:
    at MySample.Features.MyArea_5_SortFlip.MyFeature_12_Third.<>c.<MyScenario_30_Unsorted_38_Sorted>b__2_1(Step s) in C:\Users\stearm01\source\xBDD\MySample.Features\bin\Debug\netcoreapp2.1\Code\MyArea_5_SortFlip\MyFeature_12_Third.cs:line 41
   at System.Threading.ExecutionContext.RunInternal(ExecutionContext executionContext, ContextCallback callback, Object state)
--- End of stack trace from previous location where exception was thrown ---
   at System.Threading.Tasks.Task.ExecuteWithThreadLocal(Task& currentTaskSlot)
--- End of stack trace from previous location where exception was thrown ---
   at xBDD.Core.StepExecutor.ExecuteStepAsync(Step step)
--- End of inner exception stack trace ---
    at xBDD.Core.StepExceptionHandler.ProcessException(StepExecutor stepExecutor, Step step, Exception ex)
   at xBDD.Core.StepExecutor.ExecuteStepAsync(Step step)
   at xBDD.Core.ScenarioRunner.RunAsync(Boolean passWhenNoAction)
   at xBDD.Core.ScenarioBuilder.Run()
   at MySample.Features.MyArea_5_SortFlip.MyFeature_12_Third.MyScenario_30_Unsorted_38_Sorted() in C:\Users\stearm01\source\xBDD\MySample.Features\bin\Debug\netcoreapp2.1\Code\MyArea_5_SortFlip\MyFeature_12_Third.cs:line 39

Standard Output Messages:
 

Debug Trace:
My Scenario 30 Unsorted 38 Sorted
     Given my step 88 112
     When my step 89 113 failed
     Then my step 90 114


Passed   MyScenario_35_Unsorted_30_Sorted
Passed   MyScenario_34_Unsorted_31_Sorted
Passed   MyScenario_33_Unsorted_32_Sorted
Passed   MyScenario_36_Unsorted_35_Sorted
Passed   MyScenario_37_Unsorted_34_Sorted
Passed   MyScenario_38_Unsorted_33_Sorted
Failed   MyScenario_29_CompleteFailure
Error Message:
 Test method MySample.Features.MyArea_4_CompleteFailure.MyFeature_11_CompleteFailure.MyScenario_29_CompleteFailure threw exception: 
xBDD.StepException: The step 'my failed step 86' threw a 'Exception' exception with a message: 'Exception of type 'System.Exception' was thrown.'. See the inner exception for details. ---> System.Exception: Exception of type 'System.Exception' was thrown.
Stack Trace:
    at MySample.Features.MyArea_4_CompleteFailure.MyFeature_11_CompleteFailure.<>c.<MyScenario_29_CompleteFailure>b__0_1(Step s) in C:\Users\stearm01\source\xBDD\MySample.Features\bin\Debug\netcoreapp2.1\Code\MyArea_4_CompleteFailure\MyFeature_11_CompleteFailure.cs:line 21
   at System.Threading.ExecutionContext.RunInternal(ExecutionContext executionContext, ContextCallback callback, Object state)
--- End of stack trace from previous location where exception was thrown ---
   at System.Threading.Tasks.Task.ExecuteWithThreadLocal(Task& currentTaskSlot)
--- End of stack trace from previous location where exception was thrown ---
   at xBDD.Core.StepExecutor.ExecuteStepAsync(Step step)
--- End of inner exception stack trace ---
    at xBDD.Core.StepExceptionHandler.ProcessException(StepExecutor stepExecutor, Step step, Exception ex)
   at xBDD.Core.StepExecutor.ExecuteStepAsync(Step step)
   at xBDD.Core.ScenarioRunner.RunAsync(Boolean passWhenNoAction)
   at xBDD.Core.ScenarioBuilder.Run()
   at MySample.Features.MyArea_4_CompleteFailure.MyFeature_11_CompleteFailure.MyScenario_29_CompleteFailure() in C:\Users\stearm01\source\xBDD\MySample.Features\bin\Debug\netcoreapp2.1\Code\MyArea_4_CompleteFailure\MyFeature_11_CompleteFailure.cs:line 19

Standard Output Messages:
 

Debug Trace:
My Scenario 29 Complete Failure
     Given my step 85
     When my failed step 86
     Then my step 87


Passed   MyScenario_26_Passed
Passed   MyScenario_27_Passed
Passed   MyScenario_28_Passed
Failed   MyScenario_20_Failed
Error Message:
 Test method MySample.Features.MyArea_3_SomeFailed.MyFeature_8_SomeFailed.MyScenario_20_Failed threw exception: 
xBDD.StepException: The step 'my failed step 59' threw a 'Exception' exception with a message: 'Exception of type 'System.Exception' was thrown.'. See the inner exception for details. ---> System.Exception: Exception of type 'System.Exception' was thrown.
Stack Trace:
    at MySample.Features.MyArea_3_SomeFailed.MyFeature_8_SomeFailed.<>c.<MyScenario_20_Failed>b__0_1(Step s) in C:\Users\stearm01\source\xBDD\MySample.Features\bin\Debug\netcoreapp2.1\Code\MyArea_3_SomeFailed\MyFeature_8_SomeFailed.cs:line 21
   at System.Threading.ExecutionContext.RunInternal(ExecutionContext executionContext, ContextCallback callback, Object state)
--- End of stack trace from previous location where exception was thrown ---
   at System.Threading.Tasks.Task.ExecuteWithThreadLocal(Task& currentTaskSlot)
--- End of stack trace from previous location where exception was thrown ---
   at xBDD.Core.StepExecutor.ExecuteStepAsync(Step step)
--- End of inner exception stack trace ---
    at xBDD.Core.StepExceptionHandler.ProcessException(StepExecutor stepExecutor, Step step, Exception ex)
   at xBDD.Core.StepExecutor.ExecuteStepAsync(Step step)
   at xBDD.Core.ScenarioRunner.RunAsync(Boolean passWhenNoAction)
   at xBDD.Core.ScenarioBuilder.Run()
   at MySample.Features.MyArea_3_SomeFailed.MyFeature_8_SomeFailed.MyScenario_20_Failed() in C:\Users\stearm01\source\xBDD\MySample.Features\bin\Debug\netcoreapp2.1\Code\MyArea_3_SomeFailed\MyFeature_8_SomeFailed.cs:line 19

Standard Output Messages:
 

Debug Trace:
My Scenario 20 Failed
     Given my step 58
     When my failed step 59
     Then my step 60


Failed   MyScenario_21_Failed
Error Message:
 Test method MySample.Features.MyArea_3_SomeFailed.MyFeature_8_SomeFailed.MyScenario_21_Failed threw exception: 
xBDD.StepException: The step 'my step 62' threw a 'Exception' exception with a message: 'Exception of type 'System.Exception' was thrown.'. See the inner exception for details. ---> System.Exception: Exception of type 'System.Exception' was thrown.
Stack Trace:
    at MySample.Features.MyArea_3_SomeFailed.MyFeature_8_SomeFailed.<>c.<MyScenario_21_Failed>b__1_1(Step s) in C:\Users\stearm01\source\xBDD\MySample.Features\bin\Debug\netcoreapp2.1\Code\MyArea_3_SomeFailed\MyFeature_8_SomeFailed.cs:line 31
   at System.Threading.ExecutionContext.RunInternal(ExecutionContext executionContext, ContextCallback callback, Object state)
--- End of stack trace from previous location where exception was thrown ---
   at System.Threading.Tasks.Task.ExecuteWithThreadLocal(Task& currentTaskSlot)
--- End of stack trace from previous location where exception was thrown ---
   at xBDD.Core.StepExecutor.ExecuteStepAsync(Step step)
--- End of inner exception stack trace ---
    at xBDD.Core.StepExceptionHandler.ProcessException(StepExecutor stepExecutor, Step step, Exception ex)
   at xBDD.Core.StepExecutor.ExecuteStepAsync(Step step)
   at xBDD.Core.ScenarioRunner.RunAsync(Boolean passWhenNoAction)
   at xBDD.Core.ScenarioBuilder.Run()
   at MySample.Features.MyArea_3_SomeFailed.MyFeature_8_SomeFailed.MyScenario_21_Failed() in C:\Users\stearm01\source\xBDD\MySample.Features\bin\Debug\netcoreapp2.1\Code\MyArea_3_SomeFailed\MyFeature_8_SomeFailed.cs:line 29

Standard Output Messages:
 

Debug Trace:
My Scenario 21 Failed
     Given my step 61
     When my step 62
     Then my step 63


Passed   MyScenario_22_Passed
Failed   MyScenario_23_Failedd
Error Message:
 Test method MySample.Features.MyArea_3_SomeFailed.MyFeature_9_SomeSkipped.MyScenario_23_Failedd threw exception: 
xBDD.StepException: The step 'my step 68' threw a 'Exception' exception with a message: 'Exception of type 'System.Exception' was thrown.'. See the inner exception for details. ---> System.Exception: Exception of type 'System.Exception' was thrown.
Stack Trace:
    at MySample.Features.MyArea_3_SomeFailed.MyFeature_9_SomeSkipped.<>c.<MyScenario_23_Failedd>b__0_1(Step s) in C:\Users\stearm01\source\xBDD\MySample.Features\bin\Debug\netcoreapp2.1\Code\MyArea_3_SomeFailed\MyFeature_9_SomeSkipped.cs:line 21
   at System.Threading.ExecutionContext.RunInternal(ExecutionContext executionContext, ContextCallback callback, Object state)
--- End of stack trace from previous location where exception was thrown ---
   at System.Threading.Tasks.Task.ExecuteWithThreadLocal(Task& currentTaskSlot)
--- End of stack trace from previous location where exception was thrown ---
   at xBDD.Core.StepExecutor.ExecuteStepAsync(Step step)
--- End of inner exception stack trace ---
    at xBDD.Core.StepExceptionHandler.ProcessException(StepExecutor stepExecutor, Step step, Exception ex)
   at xBDD.Core.StepExecutor.ExecuteStepAsync(Step step)
   at xBDD.Core.ScenarioRunner.RunAsync(Boolean passWhenNoAction)
   at xBDD.Core.ScenarioBuilder.Run()
   at MySample.Features.MyArea_3_SomeFailed.MyFeature_9_SomeSkipped.MyScenario_23_Failedd() in C:\Users\stearm01\source\xBDD\MySample.Features\bin\Debug\netcoreapp2.1\Code\MyArea_3_SomeFailed\MyFeature_9_SomeSkipped.cs:line 19

Standard Output Messages:
 

Debug Trace:
My Scenario 23 Failedd
     Given my step 67
     When my step 68
     Then my step 69


Skipped  MyScenario_24_Skipped
Passed   MyScenario_25_Passed
Skipped  MyScenario_11
Skipped  MyScenario_12
Passed   MyScenario_13
Skipped  MyScenario_14
Skipped  MyScenario_15
Passed   MyScenario_16
Passed   MyScenario_17
Passed   MyScenario_18
Passed   MyScenario_19
Passed   MyScenario_1
Passed   MyScenario_2
Passed   MyScenario_3
Passed   MyScenario_4
Passed   MyScenario_5
Passed   MyScenario_6
Passed   MyScenario_7
Passed   MyScenario_8
Passed   MyScenario_9
Passed   MyScenario_10_WithReusableSteps
Passed   MyScenario_1_Sorted
Passed   MyScenario_2_Sorted
Passed   MyScenario_0_Unsorted

Total tests: 45. Passed: 32. Failed: 7. Skipped: 6.
Test execution time: 1.4924 Seconds

Build FAILED.
    0 Warning(s)
    0 Error(s)

Time Elapsed 00:00:02.14
